File: data_store/cpa/CPA2/DSC/CPA1 0.1 M Sucrose.txt
#FILE:02 A2 0.1 M Sucrose.ngb-sd7
#FORMAT:NETZSCH5
#IDENTITY:02 A2 0.1 M Sucrose
#DECIMAL:POINT
#SEPARATOR:SEMICOLON
#MTYPE:DSC
#INSTRUMENT:NETZSCH DSC 204F1 Phoenix
#PROJECT:Cumerr Rapid
#DATE/TIME:22.02.2016 18:12:13
#CORR. FILE:
#LABORATORY:Bioreaktor
#OPERATOR:MM
#REMARK:
#SAMPLE:0.1 M
#SAMPLE MASS /mg:29.8
#MATERIAL:DMSO+5%DMSO
#REFERENCE:Leertiegel
#REFERENCE MASS /mg:0
#TYPE OF CRUCIBLE:Pan Al, pierced lid
#SAMPLE CRUCIBLE MASS /mg:38.7
#REFERENCE CRUCIBLE MASS /mg:39.1
#CORR. CODE:000
#EXO:-1
#RANGE:-80....20/-10.0....10.0K/min
#SEGMENT:S1-5/5

##Temp./°C;Time/min;DSC/(mW/mg);Sensit./(uV/mW);Segment
    22.50900;0.0000e+000;-8.1080e-003;3.20970;1
    22.50607;2.3333e-002;-8.0522e-003;3.20969;1
    22.50400;4.6667e-002;-8.0124e-003;3.20969;1
    22.50182;7.0000e-002;-8.0443e-003;3.20969;1
    22.49806;9.3333e-002;-8.1082e-003;3.20969;1
    22.48976;    0.11667;-9.4084e-003;3.20968;1
    22.47535;    0.14000;-1.1993e-002;3.20967;1
    22.45582;    0.16333;-1.5543e-002;3.20966;1
    22.43159;    0.18667;-2.0122e-002;3.20964;1
    22.40276;    0.21000;-2.5626e-002;3.20962;1
    22.36900;    0.23333;-3.1952e-002;3.20959;1
    22.33082;    0.25667;-3.8661e-002;3.20956;1
    22.28941;    0.28000;-4.6065e-002;3.20953;1
    22.24494;    0.30333;-5.3652e-002;3.20950;1
    22.19771;    0.32667;-6.1191e-002;3.20946;1
    22.14788;    0.35000;-6.8651e-002;3.20942;1
    22.09618;    0.37333;-7.6334e-002;3.20938;1
    22.04229;    0.39667;-8.3930e-002;3.20934;1
    21.98582;    0.42000;-9.1447e-002;3.20930;1
    21.92724;    0.44333;-9.9027e-002;3.20925;1
    21.86694;    0.46667;    -0.10649;3.20921;1
    21.80506;    0.49000;    -0.11352;3.20916;1
    21.74206;    0.51333;    -0.12033;3.20911;1
    21.67871;    0.53667;    -0.12690;3.20906;1
    21.61500;    0.56000;    -0.13301;3.20901;1
    21.55000;    0.58333;    -0.13853;3.20896;1
    21.48294;    0.60667;    -0.14435;3.20891;1
    21.41212;    0.63000;    -0.15016;3.20886;1
    21.33406;    0.65333;    -0.15732;3.20879;1
    21.24724;    0.67667;    -0.16606;3.20873;1
    21.15206;    0.70000;    -0.17655;3.20865;1
    21.04841;    0.72333;    -0.18807;3.20857;1
    20.93712;    0.74667;    -0.20062;3.20848;1
    20.81906;    0.77000;    -0.21410;3.20839;1
    20.69435;    0.79333;    -0.22803;3.20829;1
    20.56365;    0.81667;    -0.24223;3.20819;1
    20.42612;    0.84000;    -0.25708;3.20808;1
    20.28200;    0.86333;    -0.27263;3.20797;1
    20.13124;    0.88667;    -0.28836;3.20785;1
    19.97453;    0.91000;    -0.30450;3.20772;1
    19.81271;    0.93333;    -0.32079;3.20759;1
    19.64829;    0.95667;    -0.33625;3.20746;1
    19.48200;    0.98000;    -0.35141;3.20732;1
    19.31318;    1.00333;    -0.36574;3.20719;1
    19.14106;    1.02667;    -0.37958;3.20705;1
    18.96676;    1.05000;    -0.39307;3.20690;1
    18.79153;    1.07333;    -0.40580;3.20676;1
    18.61612;    1.09667;    -0.41737;3.20661;1
    18.43912;    1.12000;    -0.42847;3.20647;1
    18.25906;    1.14333;    -0.43934;3.20632;1
    18.07606;    1.16667;    -0.45006;3.20616;1
    17.89018;    1.19000;    -0.46057;3.20601;1
    17.70082;    1.21333;    -0.47122;3.20585;1
    17.50788;    1.23667;    -0.48182;3.20569;1
    17.31124;    1.26000;    -0.49246;3.20552;1
    17.11047;    1.28333;    -0.50333;3.20535;1
    16.90618;    1.30667;    -0.51422;3.20517;1
    16.69818;    1.33000;    -0.52483;3.20500;1
    16.48776;    1.35333;    -0.53575;3.20481;1
    16.27447;    1.37667;    -0.54628;3.20463;1
    16.05753;    1.40000;    -0.55671;3.20444;1
    15.83624;    1.42333;    -0.56737;3.20425;1
    15.61071;    1.44667;    -0.57825;3.20405;1
    15.38112;    1.47000;    -0.58935;3.20385;1
    15.14671;    1.49333;    -0.60064;3.20364;1
    14.90765;    1.51667;    -0.61223;3.20343;1
    14.66347;    1.54000;    -0.62434;3.20321;1
    14.41429;    1.56333;    -0.63646;3.20298;1
    14.16071;    1.58667;    -0.64896;3.20275;1
    13.31329;    1.66000;    -0.68874;3.20198;2
    11.46924;    1.80000;    -0.78036;3.20025;2
     9.42218;    1.94000;    -0.89500;3.19826;2
     7.15147;    2.08000;    -1.00596;3.19597;2
     4.70194;    2.22000;    -1.11390;3.19339;2
     2.13541;    2.36000;    -1.20176;3.19057;2
    -0.36271;    2.50000;    -1.26430;3.18771;2
    -2.39659;    2.64000;    -1.22340;3.18531;2
    -3.51776;    2.78000;    -0.99265;3.18395;2
    -3.64847;    2.92000;    -0.62887;3.18379;2
    -3.11335;    3.06000;    -0.26380;3.18444;2
    -2.30953;    3.20000; 8.6480e-003;3.18541;2
    -1.53018;    3.34000;     0.17341;3.18634;2
    -0.91559;    3.48000;     0.22901;3.18707;2
    -0.45571;    3.62000;     0.22766;3.18761;2
-3.4529e-002;    3.76000;     0.21582;3.18810;2
     0.39135;    3.90000;     0.22210;3.18859;2
     0.80794;    4.04000;     0.21725;3.18907;2
     1.19171;    4.18000;     0.21066;3.18950;2
     1.54459;    4.32000;     0.19825;3.18990;2
     1.85735;    4.46000;     0.18678;3.19026;2
     2.10071;    4.60000;     0.16349;3.19053;2
     2.24394;    4.74000;     0.12867;3.19069;2
     2.30365;    4.88000; 8.7058e-002;3.19076;2
     2.31682;    5.02000; 5.3061e-002;3.19077;2
     2.31518;    5.16000; 2.9319e-002;3.19077;2
     2.31653;    5.30000; 1.6120e-002;3.19077;2
     2.33247;    5.44000; 1.0808e-002;3.19079;2
     2.36659;    5.58000; 1.2004e-002;3.19083;2
     2.41659;    5.72000; 1.6137e-002;3.19088;2
     2.48265;    5.86000; 2.1111e-002;3.19096;2
     2.56382;    6.00000; 2.7787e-002;3.19105;2
     2.65312;    6.14000; 3.4398e-002;3.19115;2
     2.74341;    6.28000; 3.8064e-002;3.19125;2
     2.82918;    6.42000; 3.9074e-002;3.19134;2
     2.90820;    6.56000; 3.8240e-002;3.19143;2
     2.93533;    6.61917; 3.7093e-002;3.19146;3
     2.94759;    6.64250; 3.6996e-002;3.19147;3
     2.95588;    6.66583; 3.6298e-002;3.19148;3
     2.95535;    6.68917; 3.3764e-002;3.19148;3
     2.94218;    6.71250; 2.8742e-002;3.19147;3
     2.91447;    6.73583; 2.0270e-002;3.19144;3
     2.87041;    6.75917; 8.9108e-003;3.19139;3
     2.80959;    6.78250;-5.4497e-003;3.19132;3
     2.73200;    6.80583;-2.3181e-002;3.19124;3
     2.63665;    6.82917;-4.3552e-002;3.19113;3
     2.52312;    6.85250;-6.6831e-002;3.19100;3
     2.39341;    6.87583;-9.2294e-002;3.19086;3
     2.24582;    6.89917;    -0.11942;3.19069;3
     2.07894;    6.92250;    -0.15051;3.19051;3
     1.89406;    6.94583;    -0.18312;3.19030;3
     1.69300;    6.96917;    -0.21633;3.19007;3
     1.47518;    6.99250;    -0.25293;3.18983;3
     1.24424;    7.01583;    -0.28931;3.18956;3
     1.00394;    7.03917;    -0.32447;3.18929;3
     0.75529;    7.06250;    -0.36046;3.18901;3
     0.49559;    7.08583;    -0.39460;3.18871;3
     0.21676;    7.10917;    -0.42993;3.18839;3
-8.3471e-002;    7.13250;    -0.47051;3.18804;3
    -0.39894;    7.15583;    -0.51040;3.18767;3
    -0.73176;    7.17917;    -0.55009;3.18728;3
    -1.08124;    7.20250;    -0.59316;3.18687;3
    -1.44129;    7.22583;    -0.63435;3.18645;3
    -1.81041;    7.24917;    -0.67434;3.18601;3
    -2.18794;    7.27250;    -0.71504;3.18556;3
    -2.57918;    7.29583;    -0.75135;3.18509;3
    -2.99494;    7.31917;    -0.79333;3.18459;3
    -3.42965;    7.34250;    -0.83896;3.18406;3
    -3.86118;    7.36583;    -0.88187;3.18353;3
    -4.28900;    7.38917;    -0.91429;3.18300;3
    -4.73012;    7.41250;    -0.94883;3.18246;3
    -5.18794;    7.43583;    -0.98727;3.18189;3
    -5.63947;    7.45917;    -1.02554;3.18132;3
    -6.06206;    7.48250;    -1.04995;3.18078;3
    -6.45700;    7.50583;    -1.06472;3.18028;3
    -6.82776;    7.52917;    -1.07615;3.17981;3
    -7.16441;    7.55250;    -1.07801;3.17938;3
    -7.46000;    7.57583;    -1.06990;3.17900;3
    -7.71771;    7.59917;    -1.05259;3.17866;3
    -7.95435;    7.62250;    -1.02884;3.17835;3
    -8.19041;    7.64583;    -1.00812;3.17805;3
    -8.42706;    7.66917;    -0.99102;3.17774;3
    -8.64547;    7.69250;    -0.97059;3.17745;3
    -8.84841;    7.71583;    -0.94386;3.17718;3
    -9.05929;    7.73917;    -0.92125;3.17691;3
    -9.28806;    7.76250;    -0.90739;3.17660;3
    -9.51241;    7.78583;    -0.89542;3.17631;3
    -9.71218;    7.80917;    -0.87511;3.17604;3
    -9.89794;    7.83250;    -0.85166;3.17579;3
   -10.08306;    7.85583;    -0.83350;3.17555;3
   -10.25441;    7.87917;    -0.81428;3.17532;3
   -10.39888;    7.90250;    -0.78716;3.17512;3
   -10.53659;    7.92583;    -0.75762;3.17494;3
   -10.68888;    7.94917;    -0.73822;3.17473;3
   -10.84829;    7.97250;    -0.72238;3.17452;3
   -10.99253;    7.99583;    -0.70358;3.17432;3
   -11.12324;    8.01917;    -0.67967;3.17414;3
   -11.25824;    8.04250;    -0.66076;3.17396;3
   -11.39971;    8.06583;    -0.64610;3.17377;3
   -11.53600;    8.08917;    -0.63008;3.17358;3
   -11.66253;    8.11250;    -0.61373;3.17341;3
   -11.78288;    8.13583;    -0.59599;3.17324;3
   -11.91212;    8.15917;    -0.57891;3.17307;3
   -12.06276;    8.18250;    -0.57209;3.17286;3
   -12.22576;    8.20583;    -0.56872;3.17264;3
   -12.38559;    8.22917;    -0.56404;3.17242;3
   -12.54735;    8.25250;    -0.55741;3.17219;3
   -12.72535;    8.27583;    -0.55767;3.17195;3
   -12.91700;    8.29917;    -0.56219;3.17168;3
   -13.10541;    8.32250;    -0.56531;3.17142;3
   -13.28741;    8.34583;    -0.56541;3.17116;3
   -13.47676;    8.36917;    -0.56675;3.17090;3
   -13.67812;    8.39250;    -0.57285;3.17062;3
   -13.88153;    8.41583;    -0.57918;3.17033;3
   -14.07782;    8.43917;    -0.58320;3.17005;3
   -14.26724;    8.46250;    -0.58463;3.16979;3
   -14.45724;    8.48583;    -0.58473;3.16952;3
   -14.65859;    8.50917;    -0.58789;3.16923;3
   -14.87153;    8.53250;    -0.59492;3.16893;3
   -15.08582;    8.55583;    -0.60269;3.16862;3
   -15.29729;    8.57917;    -0.60867;3.16832;3
   -15.50835;    8.60250;    -0.61308;3.16802;3
   -15.72065;    8.62583;    -0.61811;3.16771;3
   -15.94359;    8.64917;    -0.62222;3.16739;3
   -16.19018;    8.67250;    -0.63386;3.16704;3
   -16.45665;    8.69583;    -0.65054;3.16665;3
   -16.72235;    8.71917;    -0.66569;3.16626;3
   -16.98212;    8.74250;    -0.67661;3.16588;3
   -17.24753;    8.76583;    -0.68818;3.16550;3
   -17.52218;    8.78917;    -0.70294;3.16509;3
   -17.79288;    8.81250;    -0.71636;3.16469;3
   -18.05741;    8.83583;    -0.72416;3.16430;3
   -18.33300;    8.85917;    -0.73440;3.16389;3
   -18.62659;    8.88250;    -0.75045;3.16346;3
   -18.92082;    8.90583;    -0.76657;3.16302;3
   -19.20276;    8.92917;    -0.77623;3.16259;3
   -19.48294;    8.95250;    -0.78321;3.16217;3
   -19.77206;    8.97583;    -0.79490;3.16174;3
   -20.05806;    8.99917;    -0.80632;3.16130;3
   -20.32512;    9.02250;    -0.81073;3.16090;3
   -20.58212;    9.04583;    -0.81020;3.16051;3
   -20.84476;    9.06917;    -0.81355;3.16010;3
   -21.10924;    9.09250;    -0.81847;3.15970;3
   -21.33276;    9.11583;    -0.82489;3.15935;3
   -21.52776;    9.13917;    -6.25379;3.15905;3
   -21.72912;    9.16250;    -6.51032;3.15874;3
   -21.95353;    9.18583;    -6.57167;3.15840;3
   -22.17259;    9.20917;    -6.60983;3.15806;3
   -22.37588;    9.23250;    -6.63436;3.15774;3
   -22.57300;    9.25583;    -6.65092;3.15743;3
   -22.77041;    9.27917;    -6.66480;3.15712;3
   -22.96618;    9.30250;    -6.67469;3.15682;3
   -23.15818;    9.32583;    -6.67927;3.15651;3
   -23.34647;    9.34917;    -6.67962;3.15622;3
   -23.53371;    9.37250;    -6.67392;3.15592;3
   -23.72659;    9.39583;    -6.66483;3.15562;3
   -23.92788;    9.41917;    -6.65280;3.15530;3
   -24.14029;    9.44250;    -6.63634;3.15496;3
   -24.36976;    9.46583;    -6.61876;3.15460;3
   -24.61200;    9.48917;    -6.59641;3.15421;3
   -24.85859;    9.51250;    -6.56286;3.15382;3
   -25.10694;    9.53583;    -6.51909;3.15342;3
   -25.35494;    9.55917;    -6.46005;3.15302;3
   -25.60241;    9.58250;    -6.37989;3.15262;3
   -25.85324;    9.60583;    -6.27892;3.15221;3
   -26.10641;    9.62917;    -6.14612;3.15180;3
   -26.36235;    9.65250;    -5.96910;3.15139;3
   -26.62306;    9.67583;    -5.73857;3.15096;3
   -26.88306;    9.69917;    -5.44782;3.15054;3
   -27.14000;    9.72250;    -5.11163;3.15011;3
   -27.39482;    9.74583;    -4.75501;3.14969;3
   -27.64606;    9.76917;    -4.39151;3.14928;3
   -27.89653;    9.79250;    -4.03525;3.14887;3
   -28.14924;    9.81583;    -3.69626;3.14845;3
   -28.39894;    9.83917;    -3.37505;3.14803;3
   -28.64735;    9.86250;    -3.07692;3.14762;3
   -28.89388;    9.88583;    -2.80352;3.14721;3
   -29.13559;    9.90917;    -2.55072;3.14680;3
   -29.37306;    9.93250;    -2.32158;3.14640;3
   -29.60624;    9.95583;    -2.11445;3.14601;3
   -29.83576;    9.97917;    -1.92494;3.14562;3
   -30.06518;   10.00250;    -1.75684;3.14523;3
   -30.29335;   10.02583;    -1.60634;3.14484;3
   -30.52035;   10.04917;    -1.47035;3.14446;3
   -30.74694;   10.07250;    -1.35439;3.14407;3
   -30.97288;   10.09583;    -1.26227;3.14369;3
   -31.19853;   10.11917;    -1.27904;3.14330;3
   -31.42665;   10.14250;    -1.19696;3.14291;3
   -31.65471;   10.16583;    -1.10632;3.14252;3
   -31.88194;   10.18917;    -1.02490;3.14212;3
   -32.10894;   10.21250;    -0.95375;3.14173;3
   -32.33347;   10.23583;    -0.88862;3.14134;3
   -32.55712;   10.25917;    -0.83095;3.14095;3
   -32.78094;   10.28250;    -0.78119;3.14056;3
   -33.00412;   10.30583;    -0.73506;3.14017;3
   -33.22894;   10.32917;    -0.69586;3.13978;3
   -33.45412;   10.35250;    -0.66202;3.13939;3
   -33.67712;   10.37583;    -0.62941;3.13899;3
   -33.89935;   10.39917;    -0.60183;3.13860;3
   -34.12053;   10.42250;    -0.57749;3.13821;3
   -34.34176;   10.44583;    -0.55437;3.13782;3
   -34.56665;   10.46917;    -0.53617;3.13742;3
   -34.79247;   10.49250;    -0.52005;3.13702;3
   -35.01788;   10.51583;    -0.50448;3.13662;3
   -35.24371;   10.53917;    -0.49233;3.13622;3
   -35.46965;   10.56250;    -0.48065;3.13581;3
   -35.69853;   10.58583;    -0.47036;3.13540;3
   -35.93106;   10.60917;    -0.46382;3.13499;3
   -36.16188;   10.63250;    -0.45621;3.13457;3
   -36.38888;   10.65583;    -0.44853;3.13416;3
   -36.61671;   10.67917;    -0.44204;3.13375;3
   -36.85035;   10.70250;    -0.43656;3.13332;3
   -37.09600;   10.72583;    -0.43506;3.13288;3
   -37.34571;   10.74917;    -0.43572;3.13242;3
   -37.59012;   10.77250;    -0.43459;3.13198;3
   -37.82953;   10.79583;    -0.43036;3.13154;3
   -38.07571;   10.81917;    -0.42883;3.13109;3
   -38.32641;   10.84250;    -0.43028;3.13063;3
   -38.57053;   10.86583;    -0.42968;3.13018;3
   -38.80665;   10.88917;    -0.42483;3.12974;3
   -39.04706;   10.91250;    -0.42207;3.12929;3
   -39.29582;   10.93583;    -0.42276;3.12883;3
   -39.54124;   10.95917;    -0.42373;3.12838;3
   -39.77665;   10.98250;    -0.41997;3.12794;3
   -40.01171;   11.00583;    -0.41533;3.12750;3
   -40.25318;   11.02917;    -0.41503;3.12704;3
   -40.49277;   11.05250;    -0.41534;3.12659;3
   -40.72229;   11.07583;    -0.41137;3.12616;3
   -40.95065;   11.09917;    -0.40583;3.12573;3
   -41.18847;   11.12250;    -0.40479;3.12528;3
   -41.42923;   11.14583;    -0.40631;3.12483;3
   -41.66194;   11.16917;    -0.40426;3.12439;3
   -41.88947;   11.19250;    -0.39993;3.12395;3
   -42.12259;   11.21583;    -0.39772;3.12351;3
   -42.36006;   11.23917;    -0.39848;3.12305;3
   -42.59188;   11.26250;    -0.39729;3.12261;3
   -42.81735;   11.28583;    -0.39355;3.12218;3
   -43.04735;   11.30917;    -0.38995;3.12174;3
   -43.28494;   11.33250;    -0.39079;3.12128;3
   -43.51941;   11.35583;    -0.39182;3.12083;3
   -43.74694;   11.37917;    -0.38897;3.12039;3
   -43.97747;   11.40250;    -0.38553;3.11994;3
   -44.21706;   11.42583;    -0.38629;3.11947;3
   -44.45606;   11.44917;    -0.38824;3.11901;3
   -44.68606;   11.47250;    -0.38761;3.11856;3
   -44.91300;   11.49583;    -0.38337;3.11811;3
   -45.14518;   11.51917;    -0.38185;3.11766;3
   -45.37847;   11.54250;    -0.38259;3.11720;3
   -45.60471;   11.56583;    -0.38131;3.11676;3
   -45.82718;   11.58917;    -0.37607;3.11632;3
   -46.05418;   11.61250;    -0.37401;3.11587;3
   -46.28424;   11.63583;    -0.37458;3.11541;3
   -46.50912;   11.65917;    -0.37347;3.11497;3
   -46.72929;   11.68250;    -0.36924;3.11453;3
   -46.95365;   11.70583;    -0.36745;3.11408;3
   -47.18371;   11.72917;    -0.36770;3.11362;3
   -47.41171;   11.75250;    -0.36809;3.11317;3
   -47.63506;   11.77583;    -0.36505;3.11272;3
   -47.86076;   11.79917;    -0.36338;3.11227;3
   -48.09265;   11.82250;    -0.36357;3.11180;3
   -48.32476;   11.84583;    -0.36479;3.11133;3
   -48.55200;   11.86917;    -0.36327;3.11088;3
   -48.77982;   11.89250;    -0.36143;3.11041;3
   -49.01359;   11.91583;    -0.36143;3.10994;3
   -49.24888;   11.93917;    -0.36338;3.10946;3
   -49.47971;   11.96250;    -0.36253;3.10899;3
   -49.70906;   11.98583;    -0.36038;3.10852;3
   -49.94376;   12.00917;    -0.36037;3.10805;3
   -50.18059;   12.03250;    -0.36194;3.10756;3
   -50.41276;   12.05583;    -0.36169;3.10708;3
   -50.64088;   12.07917;    -0.35895;3.10661;3
   -50.87200;   12.10250;    -0.35803;3.10614;3
   -51.10588;   12.12583;    -0.35827;3.10566;3
   -51.33518;   12.14917;    -0.35804;3.10518;3
   -51.55988;   12.17250;    -0.35475;3.10472;3
   -51.78729;   12.19583;    -0.35317;3.10424;3
   -52.01965;   12.21917;    -0.35279;3.10376;3
   -52.25135;   12.24250;    -0.35335;3.10328;3
   -52.47900;   12.26583;    -0.35192;3.10280;3
   -52.70747;   12.28917;    -0.35006;3.10232;3
   -52.94141;   12.31250;    -0.34992;3.10183;3
   -53.17635;   12.33583;    -0.35111;3.10134;3
   -53.40665;   12.35917;    -0.35090;3.10086;3
   -53.63571;   12.38250;    -0.34897;3.10037;3
   -53.86776;   12.40583;    -0.34807;3.09988;3
   -54.10065;   12.42917;    -0.34870;3.09939;3
   -54.33147;   12.45250;    -0.34844;3.09890;3
   -54.56035;   12.47583;    -0.34624;3.09841;3
   -54.79241;   12.49917;    -0.34600;3.09792;3
   -55.02629;   12.52250;    -0.34616;3.09742;3
   -55.25859;   12.54583;    -0.34648;3.09693;3
   -55.48918;   12.56917;    -0.34502;3.09643;3
   -55.72212;   12.59250;    -0.34417;3.09593;3
   -55.95918;   12.61583;    -0.34481;3.09542;3
   -56.19553;   12.63917;    -0.34586;3.09491;3
   -56.42818;   12.66250;    -0.34522;3.09441;3
   -56.66059;   12.68583;    -0.34431;3.09391;3
   -56.89612;   12.70917;    -0.34380;3.09340;3
   -57.13171;   12.73250;    -0.34443;3.09289;3
   -57.36618;   12.75583;    -0.34429;3.09238;3
   -57.60094;   12.77917;    -0.34353;3.09187;3
   -57.83994;   12.80250;    -0.34358;3.09135;3
   -58.08153;   12.82583;    -0.34505;3.09082;3
   -58.32177;   12.84917;    -0.34568;3.09029;3
   -58.55924;   12.87250;    -0.34532;3.08977;3
   -58.79665;   12.89583;    -0.34491;3.08925;3
   -59.03435;   12.91917;    -0.34489;3.08873;3
   -59.27147;   12.94250;    -0.34495;3.08820;3
   -59.50700;   12.96583;    -0.34356;3.08768;3
   -59.74394;   12.98917;    -0.34316;3.08716;3
   -59.98500;   13.01250;    -0.34333;3.08662;3
   -60.22835;   13.03583;    -0.34454;3.08608;3
   -60.46924;   13.05917;    -0.34479;3.08555;3
   -60.70918;   13.08250;    -0.34412;3.08501;3
   -60.95047;   13.10583;    -0.34375;3.08447;3
   -61.19141;   13.12917;    -0.34413;3.08393;3
   -61.43112;   13.15250;    -0.34367;3.08339;3
   -61.66977;   13.17583;    -0.34333;3.08286;3
   -61.91100;   13.19917;    -0.34262;3.08231;3
   -62.15577;   13.22250;    -0.34281;3.08176;3
   -62.40224;   13.24583;    -0.34363;3.08121;3
   -62.64741;   13.26917;    -0.34388;3.08065;3
   -62.89153;   13.29250;    -0.34437;3.08010;3
   -63.13312;   13.31583;    -0.34439;3.07955;3
   -63.37341;   13.33917;    -0.34335;3.07900;3
   -63.61635;   13.36250;    -0.34259;3.07845;3
   -63.86200;   13.38583;    -0.34319;3.07788;3
   -64.10912;   13.40917;    -0.34361;3.07732;3
   -64.35641;   13.43250;    -0.34403;3.07675;3
   -64.60247;   13.45583;    -0.34407;3.07618;3
   -64.84824;   13.47917;    -0.34365;3.07562;3
   -65.09206;   13.50250;    -0.34318;3.07506;3
   -65.33371;   13.52583;    -0.34210;3.07450;3
   -65.57271;   13.54917;    -0.34087;3.07394;3
   -65.80982;   13.57250;    -0.33912;3.07339;3
   -66.04553;   13.59583;    -0.33743;3.07285;3
   -66.27877;   13.61917;    -0.33564;3.07230;3
   -66.50847;   13.64250;    -0.33346;3.07177;3
   -66.73371;   13.66583;    -0.33023;3.07124;3
   -66.95459;   13.68917;    -0.32688;3.07073;3
   -67.17047;   13.71250;    -0.32274;3.07022;3
   -67.38129;   13.73583;    -0.31852;3.06973;3
   -67.58965;   13.75917;    -0.31342;3.06924;3
   -67.79935;   13.78250;    -0.30982;3.06874;3
   -68.00965;   13.80583;    -0.30706;3.06825;3
   -68.21865;   13.82917;    -0.30438;3.06775;3
   -68.42788;   13.85250;    -0.30175;3.06726;3
   -68.63953;   13.87583;    -0.29977;3.06676;3
   -68.85647;   13.89917;    -0.29913;3.06624;3
   -69.07688;   13.92250;    -0.29949;3.06572;3
   -69.29847;   13.94583;    -0.29979;3.06519;3
   -69.52124;   13.96917;    -0.29988;3.06466;3
   -69.74812;   13.99250;    -0.30046;3.06412;3
   -69.97947;   14.01583;    -0.30233;3.06357;3
   -70.21371;   14.03917;    -0.30453;3.06300;3
   -70.44971;   14.06250;    -0.30607;3.06244;3
   -70.68824;   14.08583;    -0.30769;3.06187;3
   -70.92823;   14.10917;    -0.31000;3.06129;3
   -71.16635;   14.13250;    -0.31166;3.06071;3
   -71.40247;   14.15583;    -0.31194;3.06014;3
   -71.63741;   14.17917;    -0.31244;3.05957;3
   -71.87047;   14.20250;    -0.31258;3.05901;3
   -72.10018;   14.22583;    -0.31182;3.05845;3
   -72.32865;   14.24917;    -0.31031;3.05790;3
   -72.55677;   14.27250;    -0.30984;3.05734;3
   -72.78529;   14.29583;    -0.30859;3.05678;3
   -73.01229;   14.31917;    -0.30752;3.05623;3
   -73.23788;   14.34250;    -0.30618;3.05568;3
   -73.46171;   14.36583;    -0.30529;3.05513;3
   -73.68429;   14.38917;    -0.30376;3.05458;3
   -73.90441;   14.41250;    -0.30156;3.05404;3
   -74.12324;   14.43583;    -0.29993;3.05350;3
   -74.34000;   14.45917;    -0.29827;3.05297;3
   -74.55500;   14.48250;    -0.29578;3.05244;3
   -74.76906;   14.50583;    -0.29427;3.05191;3
   -74.98429;   14.52917;    -0.29253;3.05138;3
   -75.20159;   14.55250;    -0.29117;3.05084;3
   -75.42071;   14.57583;    -0.29081;3.05029;3
   -75.64035;   14.59917;    -0.29007;3.04975;3
   -75.86141;   14.62250;    -0.28952;3.04920;3
   -76.08606;   14.64583;    -0.28986;3.04863;3
   -76.31329;   14.66917;    -0.29081;3.04807;3
   -76.54282;   14.69250;    -0.29184;3.04749;3
   -76.77324;   14.71583;    -0.29326;3.04691;3
   -77.00347;   14.73917;    -0.29363;3.04634;3
   -77.23347;   14.76250;    -0.29402;3.04576;3
   -77.46518;   14.78583;    -0.29460;3.04517;3
   -77.69571;   14.80917;    -0.29547;3.04459;3
   -77.92312;   14.83250;    -0.29504;3.04402;3
   -78.14918;   14.85583;    -0.29385;3.04345;3
   -78.38047;   14.87917;    -0.29400;3.04286;3
   -78.61735;   14.90250;    -0.29548;3.04226;3
   -78.85406;   14.92583;    -0.29717;3.04166;3
   -79.08800;   14.94917;    -0.29692;3.04106;3
   -79.32153;   14.97250;    -0.29690;3.04047;3
   -79.55557;   14.99583;    -0.29707;3.03987;3
   -80.21614;   15.06917;    -0.28805;3.03818;4
   -81.17571;   15.20917;    -0.24892;3.03571;4
   -81.77182;   15.34917;    -0.18245;3.03416;4
   -81.87047;   15.48917;-8.6837e-002;3.03391;4
   -81.58700;   15.62917; 5.6781e-003;3.03464;4
   -81.16618;   15.76917; 5.3230e-002;3.03573;4
   -80.78812;   15.90917; 6.3469e-002;3.03671;4
   -80.50347;   16.04917; 5.4547e-002;3.03744;4
   -80.31300;   16.18917; 4.2498e-002;3.03793;4
   -80.18959;   16.32917; 2.6627e-002;3.03824;4
   -80.07218;   16.46917; 2.0441e-002;3.03855;4
   -79.91800;   16.60917; 2.6295e-002;3.03894;4
   -79.75900;   16.74917; 2.8029e-002;3.03935;4
   -79.64706;   16.88917; 2.2570e-002;3.03963;4
   -79.61359;   17.02917; 1.0071e-002;3.03972;4
   -79.66729;   17.16917;-6.0341e-003;3.03958;4
   -79.78953;   17.30917;-2.2126e-002;3.03927;4
   -79.93424;   17.44917;-3.2097e-002;3.03890;4
   -80.04282;   17.58917;-3.0213e-002;3.03862;4
   -80.08423;   17.72917;-1.9169e-002;3.03852;4
   -80.07500;   17.86917;-8.2485e-003;3.03854;4
   -80.06259;   18.00917;-3.3107e-003;3.03857;4
   -80.07259;   18.14917;-6.7402e-003;3.03854;4
   -80.09941;   18.28917;-1.0010e-002;3.03848;4
   -80.11782;   18.42917;-1.0120e-002;3.03843;4
   -80.12041;   18.56917;-7.6595e-003;3.03842;4
   -80.12006;   18.70917;-4.5839e-003;3.03842;4
   -80.12418;   18.84917;-5.7889e-003;3.03841;4
   -80.10335;   18.98917;-3.8845e-003;3.03847;4
   -80.05518;   19.12917; 4.7359e-003;3.03859;4
   -80.01847;   19.26917; 3.1185e-003;3.03868;4
   -80.02465;   19.40917;-3.2680e-003;3.03867;4
   -80.05682;   19.54917;-1.0835e-002;3.03859;4
   -80.08453;   19.68917;-1.0355e-002;3.03851;4
   -80.09300;   19.82917;-7.3978e-003;3.03849;4
   -80.04300;   19.96917; 4.9785e-004;3.03862;4
   -80.02936;   20.02417; 1.2900e-003;3.03866;5
   -80.01540;   20.04750; 6.1596e-004;3.03869;5
   -79.94508;   20.07083; 2.5623e-003;3.03887;5
   -79.81038;   20.09417; 1.3295e-002;3.03922;5
   -79.65203;   20.11750; 3.3012e-002;3.03962;5
   -79.49295;   20.14083; 5.8890e-002;3.04003;5
   -79.30200;   20.16417; 8.8084e-002;3.04052;5
   -79.08169;   20.18750;     0.11818;3.04108;5
   -78.83812;   20.21083;     0.14716;3.04170;5
   -78.57803;   20.23417;     0.17435;3.04236;5
   -78.30720;   20.25750;     0.19881;3.04305;5
   -78.02982;   20.28083;     0.22056;3.04375;5
   -77.74913;   20.30417;     0.23944;3.04446;5
   -77.46738;   20.32750;     0.25580;3.04517;5
   -77.18638;   20.35083;     0.26936;3.04588;5
   -76.90720;   20.37417;     0.28094;3.04658;5
   -76.63034;   20.39750;     0.29038;3.04727;5
   -76.35628;   20.42083;     0.29804;3.04796;5
   -76.08515;   20.44417;     0.30409;3.04864;5
   -75.81679;   20.46750;     0.30888;3.04931;5
   -75.55161;   20.49083;     0.31254;3.04997;5
   -75.28936;   20.51417;     0.31515;3.05062;5
   -75.03018;   20.53750;     0.31719;3.05126;5
   -74.77361;   20.56083;     0.31841;3.05190;5
   -74.51980;   20.58417;     0.31924;3.05252;5
   -74.26875;   20.60750;     0.31963;3.05314;5
   -74.02033;   20.63083;     0.31961;3.05376;5
   -73.77461;   20.65417;     0.31913;3.05436;5
   -73.53164;   20.67750;     0.31829;3.05496;5
   -73.29085;   20.70083;     0.31691;3.05555;5
   -73.05248;   20.72417;     0.31559;3.05613;5
   -72.81608;   20.74750;     0.31429;3.05671;5
   -72.58187;   20.77083;     0.31272;3.05728;5
   -72.34956;   20.79417;     0.31110;3.05785;5
   -72.11885;   20.81750;     0.30953;3.05841;5
   -71.88956;   20.84083;     0.30792;3.05896;5
   -71.66157;   20.86417;     0.30647;3.05952;5
   -71.43485;   20.88750;     0.30501;3.06007;5
   -71.20948;   20.91083;     0.30362;3.06061;5
   -70.98503;   20.93417;     0.30239;3.06115;5
   -70.76144;   20.95750;     0.30114;3.06169;5
   -70.53857;   20.98083;     0.30000;3.06223;5
   -70.31648;   21.00417;     0.29881;3.06276;5
   -70.09490;   21.02750;     0.29783;3.06329;5
   -69.87405;   21.05083;     0.29704;3.06382;5
   -69.65357;   21.07417;     0.29625;3.06435;5
   -69.43333;   21.09750;     0.29549;3.06487;5
   -69.21303;   21.12083;     0.29505;3.06540;5
   -68.99290;   21.14417;     0.29466;3.06592;5
   -68.77289;   21.16750;     0.29430;3.06644;5
   -68.55279;   21.19083;     0.29409;3.06696;5
   -68.33243;   21.21417;     0.29401;3.06748;5
   -68.11202;   21.23750;     0.29398;3.06800;5
   -67.89130;   21.26083;     0.29407;3.06853;5
   -67.67025;   21.28417;     0.29436;3.06905;5
   -67.44872;   21.30750;     0.29463;3.06957;5
   -67.22697;   21.33083;     0.29496;3.07009;5
   -67.00487;   21.35417;     0.29548;3.07061;5
   -66.78228;   21.37750;     0.29599;3.07113;5
   -66.55926;   21.40083;     0.29652;3.07165;5
   -66.33566;   21.42417;     0.29720;3.07217;5
   -66.11151;   21.44750;     0.29799;3.07269;5
   -65.88695;   21.47083;     0.29879;3.07322;5
   -65.66187;   21.49417;     0.29964;3.07374;5
   -65.43638;   21.51750;     0.30050;3.07426;5
   -65.21021;   21.54083;     0.30135;3.07478;5
   -64.98320;   21.56417;     0.30231;3.07531;5
   -64.75587;   21.58750;     0.30330;3.07583;5
   -64.52807;   21.61083;     0.30437;3.07636;5
   -64.29962;   21.63417;     0.30546;3.07688;5
   -64.07062;   21.65750;     0.30651;3.07741;5
   -63.84108;   21.68083;     0.30761;3.07793;5
   -63.61095;   21.70417;     0.30872;3.07846;5
   -63.38044;   21.72750;     0.30972;3.07898;5
   -63.14952;   21.75083;     0.31086;3.07951;5
   -62.91813;   21.77417;     0.31201;3.08004;5
   -62.68608;   21.79750;     0.31311;3.08056;5
   -62.45370;   21.82083;     0.31437;3.08109;5
   -62.22095;   21.84417;     0.31544;3.08161;5
   -61.98779;   21.86750;     0.31654;3.08214;5
   -61.75407;   21.89083;     0.31761;3.08267;5
   -61.52002;   21.91417;     0.31872;3.08319;5
   -61.28546;   21.93750;     0.31987;3.08372;5
   -61.05069;   21.96083;     0.32096;3.08425;5
   -60.81575;   21.98417;     0.32201;3.08477;5
   -60.58046;   22.00750;     0.32308;3.08530;5
   -60.34462;   22.03083;     0.32414;3.08582;5
   -60.10867;   22.05417;     0.32518;3.08635;5
   -59.87241;   22.07750;     0.32617;3.08687;5
   -59.63618;   22.10083;     0.32716;3.08740;5
   -59.39977;   22.12417;     0.32809;3.08792;5
   -59.16308;   22.14750;     0.32899;3.08844;5
   -58.92620;   22.17083;     0.33010;3.08897;5
   -58.68902;   22.19417;     0.33090;3.08949;5
   -58.45182;   22.21750;     0.33181;3.09001;5
   -58.21444;   22.24083;     0.33271;3.09053;5
   -57.97685;   22.26417;     0.33356;3.09105;5
   -57.73926;   22.28750;     0.33445;3.09157;5
   -57.50148;   22.31083;     0.33531;3.09209;5
   -57.26364;   22.33417;     0.33603;3.09260;5
   -57.02570;   22.35750;     0.33681;3.09312;5
   -56.78777;   22.38083;     0.33742;3.09364;5
   -56.54977;   22.40417;     0.33820;3.09415;5
   -56.31172;   22.42750;     0.33891;3.09466;5
   -56.07372;   22.45083;     0.33954;3.09518;5
   -55.83585;   22.47417;     0.34010;3.09569;5
   -55.59790;   22.49750;     0.34072;3.09620;5
   -55.36003;   22.52083;     0.34127;3.09671;5
   -55.12208;   22.54417;     0.34191;3.09722;5
   -54.88411;   22.56750;     0.34229;3.09773;5
   -54.64611;   22.59083;     0.34286;3.09823;5
   -54.40833;   22.61417;     0.34340;3.09874;5
   -54.17067;   22.63750;     0.34388;3.09924;5
   -53.93290;   22.66083;     0.34420;3.09975;5
   -53.69503;   22.68417;     0.34470;3.10025;5
   -53.45725;   22.70750;     0.34502;3.10075;5
   -53.21944;   22.73083;     0.34535;3.10125;5
   -52.98185;   22.75417;     0.34582;3.10175;5
   -52.74433;   22.77750;     0.34616;3.10225;5
   -52.50670;   22.80083;     0.34647;3.10274;5
   -52.26902;   22.82417;     0.34682;3.10324;5
   -52.03139;   22.84750;     0.34692;3.10374;5
   -51.79390;   22.87083;     0.34721;3.10423;5
   -51.55648;   22.89417;     0.34747;3.10472;5
   -51.31910;   22.91750;     0.34772;3.10522;5
   -51.08187;   22.94083;     0.34796;3.10571;5
   -50.84457;   22.96417;     0.34807;3.10620;5
   -50.60741;   22.98750;     0.34829;3.10668;5
   -50.37051;   23.01083;     0.34856;3.10717;5
   -50.13357;   23.03417;     0.34865;3.10766;5
   -49.89664;   23.05750;     0.34885;3.10814;5
   -49.65977;   23.08083;     0.34893;3.10863;5
   -49.42287;   23.10417;     0.34924;3.10911;5
   -49.18620;   23.12750;     0.34930;3.10959;5
   -48.94957;   23.15083;     0.34947;3.11007;5
   -48.71289;   23.17417;     0.34969;3.11055;5
   -48.47608;   23.19750;     0.35001;3.11103;5
   -48.23948;   23.22083;     0.35015;3.11151;5
   -48.00297;   23.24417;     0.35040;3.11198;5
   -47.76643;   23.26750;     0.35066;3.11246;5
   -47.53002;   23.29083;     0.35103;3.11293;5
   -47.29354;   23.31417;     0.35147;3.11341;5
   -47.05718;   23.33750;     0.35191;3.11388;5
   -46.82059;   23.36083;     0.35245;3.11435;5
   -46.58410;   23.38417;     0.35306;3.11482;5
   -46.34785;   23.40750;     0.35374;3.11529;5
   -46.11159;   23.43083;     0.35464;3.11576;5
   -45.87531;   23.45417;     0.35552;3.11622;5
   -45.63915;   23.47750;     0.35645;3.11669;5
   -45.40285;   23.50083;     0.35763;3.11715;5
   -45.16675;   23.52417;     0.35879;3.11762;5
   -44.93061;   23.54750;     0.36004;3.11808;5
   -44.69470;   23.57083;     0.36138;3.11854;5
   -44.45885;   23.59417;     0.36271;3.11900;5
   -44.22300;   23.61750;     0.36411;3.11946;5
   -43.98707;   23.64083;     0.36537;3.11992;5
   -43.75133;   23.66417;     0.36684;3.12038;5
   -43.51569;   23.68750;     0.36812;3.12083;5
   -43.28010;   23.71083;     0.36940;3.12129;5
   -43.04433;   23.73417;     0.37065;3.12174;5
   -42.80872;   23.75750;     0.37189;3.12219;5
   -42.57303;   23.78083;     0.37304;3.12265;5
   -42.33728;   23.80417;     0.37412;3.12310;5
   -42.10148;   23.82750;     0.37526;3.12355;5
   -41.86589;   23.85083;     0.37628;3.12400;5
   -41.63028;   23.87417;     0.37728;3.12445;5
   -41.39472;   23.89750;     0.37820;3.12489;5
   -41.15938;   23.92083;     0.37911;3.12534;5
   -40.92405;   23.94417;     0.37995;3.12578;5
   -40.68869;   23.96750;     0.38075;3.12623;5
   -40.45334;   23.99083;     0.38156;3.12667;5
   -40.21816;   24.01417;     0.38219;3.12711;5
   -39.98308;   24.03750;     0.38290;3.12755;5
   -39.74790;   24.06083;     0.38363;3.12799;5
   -39.51259;   24.08417;     0.38436;3.12843;5
   -39.27733;   24.10750;     0.38504;3.12887;5
   -39.04215;   24.13083;     0.38569;3.12930;5
   -38.80685;   24.15417;     0.38639;3.12974;5
   -38.57169;   24.17750;     0.38688;3.13017;5
   -38.33662;   24.20083;     0.38750;3.13061;5
   -38.10144;   24.22417;     0.38813;3.13104;5
   -37.86636;   24.24750;     0.38882;3.13147;5
   -37.63120;   24.27083;     0.38951;3.13190;5
   -37.39613;   24.29417;     0.39006;3.13233;5
   -37.16098;   24.31750;     0.39057;3.13276;5
   -36.92580;   24.34083;     0.39137;3.13319;5
   -36.69072;   24.36417;     0.39198;3.13361;5
   -36.45554;   24.38750;     0.39259;3.13404;5
   -36.22046;   24.41083;     0.39326;3.13446;5
   -35.98526;   24.43417;     0.39392;3.13489;5
   -35.75013;   24.45750;     0.39461;3.13531;5
   -35.51508;   24.48083;     0.39503;3.13573;5
   -35.27990;   24.50417;     0.39590;3.13615;5
   -35.04484;   24.52750;     0.39656;3.13657;5
   -34.80975;   24.55083;     0.39723;3.13699;5
   -34.57480;   24.57417;     0.39789;3.13741;5
   -34.33977;   24.59750;     0.39856;3.13782;5
   -34.10475;   24.62083;     0.39921;3.13824;5
   -33.86989;   24.64417;     0.40001;3.13866;5
   -33.63497;   24.66750;     0.40073;3.13907;5
   -33.40010;   24.69083;     0.40146;3.13948;5
   -33.16523;   24.71417;     0.40213;3.13989;5
   -32.93039;   24.73750;     0.40284;3.14030;5
   -32.69564;   24.76083;     0.40362;3.14071;5
   -32.46087;   24.78417;     0.40435;3.14112;5
   -32.22603;   24.80750;     0.40511;3.14153;5
   -31.99123;   24.83083;     0.40591;3.14193;5
   -31.75643;   24.85417;     0.40669;3.14234;5
   -31.52175;   24.87750;     0.40736;3.14274;5
   -31.28700;   24.90083;     0.40818;3.14315;5
   -31.05231;   24.92417;     0.40910;3.14355;5
   -30.81767;   24.94750;     0.40987;3.14395;5
   -30.58300;   24.97083;     0.41076;3.14435;5
   -30.34825;   24.99417;     0.41161;3.14475;5
   -30.11349;   25.01750;     0.41245;3.14515;5
   -29.87880;   25.04083;     0.41321;3.14555;5
   -29.64398;   25.06417;     0.41421;3.14594;5
   -29.40921;   25.08750;     0.41517;3.14634;5
   -29.17434;   25.11083;     0.41605;3.14674;5
   -28.93959;   25.13417;     0.41699;3.14713;5
   -28.70490;   25.15750;     0.41792;3.14752;5
   -28.47018;   25.18083;     0.41884;3.14791;5
   -28.23566;   25.20417;     0.41976;3.14830;5
   -28.00108;   25.22750;     0.42077;3.14869;5
   -27.76661;   25.25083;     0.42170;3.14908;5
   -27.53213;   25.27417;     0.42273;3.14947;5
   -27.29785;   25.29750;     0.42371;3.14985;5
   -27.06339;   25.32083;     0.42475;3.15024;5
   -26.82897;   25.34417;     0.42574;3.15062;5
   -26.59436;   25.36750;     0.42685;3.15101;5
   -26.35990;   25.39083;     0.42794;3.15139;5
   -26.12530;   25.41417;     0.42909;3.15177;5
   -25.89085;   25.43750;     0.43019;3.15215;5
   -25.65643;   25.46083;     0.43134;3.15253;5
   -25.42184;   25.48417;     0.43252;3.15291;5
   -25.18725;   25.50750;     0.43368;3.15329;5
   -24.95277;   25.53083;     0.43488;3.15366;5
   -24.71833;   25.55417;     0.43610;3.15404;5
   -24.48380;   25.57750;     0.43738;3.15442;5
   -24.24943;   25.60083;     0.43862;3.15479;5
   -24.01502;   25.62417;     0.43996;3.15516;5
   -23.78064;   25.64750;     0.44129;3.15553;5
   -23.54631;   25.67083;     0.44265;3.15590;5
   -23.31213;   25.69417;     0.44404;3.15627;5
   -23.07793;   25.71750;     0.44540;3.15664;5
   -22.84367;   25.74083;     0.44678;3.15701;5
   -22.60936;   25.76417;     0.44827;3.15737;5
   -22.37510;   25.78750;     0.44972;3.15774;5
   -22.14070;   25.81083;     0.45125;3.15811;5
   -21.90638;   25.83417;     0.45284;3.15847;5
   -21.67210;   25.85750;     0.45437;3.15883;5
   -21.43779;   25.88083;     0.45607;3.15919;5
   -21.20336;   25.90417;     0.45773;3.15955;5
   -20.96889;   25.92750;     0.45939;3.15991;5
   -20.73459;   25.95083;     0.46121;3.16027;5
   -20.50049;   25.97417;     0.46305;3.16063;5
   -20.26644;   25.99750;     0.46499;3.16099;5
   -20.03223;   26.02083;     0.46678;3.16134;5
   -19.79798;   26.04417;     0.46881;3.16170;5
   -19.56364;   26.06750;     0.47076;3.16205;5
   -19.32920;   26.09083;     0.47283;3.16240;5
   -19.09482;   26.11417;     0.47488;3.16276;5
   -18.86057;   26.13750;     0.47701;3.16311;5
   -18.62631;   26.16083;     0.47913;3.16346;5
   -18.39184;   26.18417;     0.48134;3.16381;5
   -18.15741;   26.20750;     0.48358;3.16415;5
   -17.92318;   26.23083;     0.48592;3.16450;5
   -17.68884;   26.25417;     0.48819;3.16485;5
   -17.45466;   26.27750;     0.49061;3.16519;5
   -17.22061;   26.30083;     0.49306;3.16553;5
   -16.98659;   26.32417;     0.49563;3.16588;5
   -16.75261;   26.34750;     0.49807;3.16622;5
   -16.51851;   26.37083;     0.50083;3.16656;5
   -16.28452;   26.39417;     0.50363;3.16690;5
   -16.05043;   26.41750;     0.50636;3.16724;5
   -15.81648;   26.44083;     0.50939;3.16758;5
   -15.58254;   26.46417;     0.51245;3.16791;5
   -15.34844;   26.48750;     0.51558;3.16825;5
   -15.11444;   26.51083;     0.51890;3.16858;5
   -14.88030;   26.53417;     0.52216;3.16892;5
   -14.64616;   26.55750;     0.52562;3.16925;5
   -14.41208;   26.58083;     0.52926;3.16958;5
   -14.17787;   26.60417;     0.53296;3.16991;5
   -13.94380;   26.62750;     0.53680;3.17024;5
   -13.70959;   26.65083;     0.54076;3.17057;5
   -13.47538;   26.67417;     0.54492;3.17090;5
   -13.24123;   26.69750;     0.54912;3.17123;5
   -13.00711;   26.72083;     0.55351;3.17155;5
   -12.77311;   26.74417;     0.55812;3.17188;5
   -12.53913;   26.76750;     0.56287;3.17220;5
   -12.30513;   26.79083;     0.56771;3.17253;5
   -12.07118;   26.81417;     0.57284;3.17285;5
   -11.83731;   26.83750;     0.57800;3.17317;5
   -11.60348;   26.86083;     0.58337;3.17349;5
   -11.36969;   26.88417;     0.58909;3.17381;5
   -11.13592;   26.90750;     0.59494;3.17413;5
   -10.90202;   26.93083;     0.60114;3.17444;5
   -10.66813;   26.95417;     0.60740;3.17476;5
   -10.43420;   26.97750;     0.61405;3.17507;5
   -10.20011;   27.00083;     0.62084;3.17539;5
    -9.96608;   27.02417;     0.62788;3.17570;5
    -9.73190;   27.04750;     0.63537;3.17601;5
    -9.49784;   27.07083;     0.64312;3.17633;5
    -9.26379;   27.09417;     0.65117;3.17664;5
    -9.02982;   27.11750;     0.65959;3.17695;5
    -8.79603;   27.14083;     0.66821;3.17725;5
    -8.56218;   27.16417;     0.67723;3.17756;5
    -8.32841;   27.18750;     0.68671;3.17787;5
    -8.09479;   27.21083;     0.69650;3.17817;5
    -7.86128;   27.23417;     0.70674;3.17848;5
    -7.62777;   27.25750;     0.71745;3.17878;5
    -7.39403;   27.28083;     0.72853;3.17908;5
    -7.16033;   27.30417;     0.74006;3.17938;5
    -6.92664;   27.32750;     0.75217;3.17968;5
    -6.69287;   27.35083;     0.76473;3.17998;5
    -6.45915;   27.37417;     0.77774;3.18028;5
    -6.22554;   27.39750;     0.79144;3.18058;5
    -5.99189;   27.42083;     0.80571;3.18087;5
    -5.75815;   27.44417;     0.82054;3.18117;5
    -5.52451;   27.46750;     0.83596;3.18146;5
    -5.29092;   27.49083;     0.85228;3.18176;5
    -5.05739;   27.51417;     0.86907;3.18205;5
    -4.82384;   27.53750;     0.88655;3.18234;5
    -4.59030;   27.56083;     0.90488;3.18263;5
    -4.35677;   27.58417;     0.92391;3.18292;5
    -4.12326;   27.60750;     0.94383;3.18321;5
    -3.88990;   27.63083;     0.96447;3.18349;5
    -3.65654;   27.65417;     0.98580;3.18378;5
    -3.42320;   27.67750;     1.00833;3.18407;5
    -3.18992;   27.70083;     1.03158;3.18435;5
    -2.95651;   27.72417;     1.05558;3.18463;5
    -2.72331;   27.74750;     1.08084;3.18491;5
    -2.49007;   27.77083;     1.10682;3.18520;5
    -2.25679;   27.79417;     1.13379;3.18548;5
    -2.02357;   27.81750;     1.16164;3.18575;5
    -1.79031;   27.84083;     1.19054;3.18603;5
    -1.55707;   27.86417;     1.22050;3.18631;5
    -1.32384;   27.88750;     1.25159;3.18659;5
    -1.09074;   27.91083;     1.28354;3.18686;5
    -0.85754;   27.93417;     1.31649;3.18714;5
    -0.62444;   27.95750;     1.35064;3.18741;5
    -0.39133;   27.98083;     1.38555;3.18768;5
    -0.15818;   28.00417;     1.42180;3.18795;5
 7.4869e-002;   28.02750;     1.45876;3.18822;5
     0.30779;   28.05083;     1.49755;3.18849;5
     0.54077;   28.07417;     1.53670;3.18876;5
     0.77361;   28.09750;     1.57698;3.18903;5
     1.00667;   28.12083;     1.61827;3.18929;5
     1.23957;   28.14417;     1.66055;3.18956;5
     1.47249;   28.16750;     1.70398;3.18982;5
     1.70539;   28.19083;     1.74852;3.19009;5
     1.93833;   28.21417;     1.79383;3.19035;5
     2.17130;   28.23750;     1.83995;3.19061;5
     2.40410;   28.26083;     1.88728;3.19087;5
     2.63692;   28.28417;     1.93546;3.19113;5
     2.86972;   28.30750;     1.98468;3.19139;5
     3.10233;   28.33083;     2.03472;3.19164;5
     3.33505;   28.35417;     2.08564;3.19190;5
     3.56782;   28.37750;     2.13722;3.19216;5
     3.80048;   28.40083;     2.18995;3.19241;5
     4.03305;   28.42417;     2.24323;3.19266;5
     4.26561;   28.44750;     2.29757;3.19292;5
     4.49818;   28.47083;     2.35264;3.19317;5
     4.73067;   28.49417;     2.40844;3.19342;5
     4.96316;   28.51750;     2.46489;3.19367;5
     5.19567;   28.54083;     2.52223;3.19392;5
     5.42815;   28.56417;     2.57995;3.19416;5
     5.66061;   28.58750;     2.63859;3.19441;5
     5.89289;   28.61083;     2.69792;3.19465;5
     6.12531;   28.63417;     2.75768;3.19490;5
     6.35787;   28.65750;     2.81792;3.19514;5
     6.59054;   28.68083;     2.87872;3.19538;5
     6.82316;   28.70417;     2.94020;3.19563;5
     7.05593;   28.72750;     3.00155;3.19587;5
     7.28862;   28.75083;     3.06331;3.19611;5
     7.52128;   28.77417;     3.12517;3.19635;5
     7.75398;   28.79750;     3.18721;3.19658;5
     7.98692;   28.82083;     3.24915;3.19682;5
     8.21961;   28.84417;     3.31115;3.19706;5
     8.45223;   28.86750;     3.37304;3.19729;5
     8.68493;   28.89083;     3.43483;3.19753;5
     8.91766;   28.91417;     3.49653;3.19776;5
     9.15049;   28.93750;     3.55944;3.19799;5
     9.38338;   28.96083;     3.62304;3.19822;5
     9.61631;   28.98417;     3.68794;3.19845;5
     9.84918;   29.00750;     3.74643;3.19868;5
    10.08197;   29.03083;     3.80584;3.19891;5
    10.31503;   29.05417;     3.86203;3.19914;5
    10.54807;   29.07750;     3.91857;3.19936;5
    10.78125;   29.10083;     3.97014;3.19959;5
    11.01449;   29.12417;     4.01774;3.19982;5
    11.24767;   29.14750;     4.06114;3.20004;5
    11.48103;   29.17083;     4.09875;3.20026;5
    11.71449;   29.19417;     4.13416;3.20048;5
    11.94823;   29.21750;     4.17351;3.20071;5
    12.18200;   29.24083;     4.19826;3.20093;5
    12.41592;   29.26417;     4.20575;3.20115;5
    12.64985;   29.28750;     4.20996;3.20136;5
    12.88389;   29.31083;     4.21770;3.20158;5
    13.11805;   29.33417;     4.22743;3.20180;5
    13.35239;   29.35750;     4.23538;3.20202;5
    13.58695;   29.38083;     4.23932;3.20223;5
    13.82167;   29.40417;     4.23629;3.20245;5
    14.05661;   29.42750;     4.22847;3.20266;5
    14.29208;   29.45083;     4.21723;3.20287;5
    14.52818;   29.47417;     4.18481;3.20309;5
    14.76482;   29.49750;     4.11544;3.20330;5
    15.00203;   29.52083;     3.99143;3.20351;5
    15.24000;   29.54417;     3.79990;3.20372;5
    15.47844;   29.56750;     3.56636;3.20393;5
    15.71738;   29.59083;     3.34279;3.20414;5
    15.95679;   29.61417;     3.13420;3.20435;5
    16.19648;   29.63750;     2.94118;3.20456;5
    16.43615;   29.66083;     2.76326;3.20477;5
    16.67562;   29.68417;     2.59923;3.20498;5
    16.91497;   29.70750;     2.44834;3.20518;5
    17.15380;   29.73083;     2.30923;3.20539;5
    17.39234;   29.75417;     2.18121;3.20559;5
    17.63051;   29.77750;     2.06339;3.20579;5
    17.86833;   29.80083;     1.95499;3.20599;5
    18.10569;   29.82417;     1.85523;3.20619;5
    18.34257;   29.84750;     1.76339;3.20639;5
    18.57921;   29.87083;     1.67902;3.20658;5
    18.81544;   29.89417;     1.60143;3.20678;5
    19.05149;   29.91750;     1.52995;3.20697;5
    19.28758;   29.94083;     1.46431;3.20716;5
    19.52310;   29.96417;     1.40387;3.20736;5
    19.75833;   29.98750;     1.34848;3.20755;5
    19.99300;   30.01083;     1.29743;3.20774;5